<?xml version="1.0"?>

<robot xmlns:xacro="http://ros.org/wiki/xacro">

  <xacro:macro name="gun_tullet" params="prefix parent pos_x pos_z">
    <joint name="${prefix}_base1_joint" type="fixed">
      <parent link="${parent}"/>
      <child link="${prefix}_base1_link"/>
      <origin rpy="0 0 0" xyz="${pos_x} 0 ${pos_z}"/>
    </joint>
 
    <link name="${prefix}_base1_link">
      <visual>
        <origin xyz="0 0 0" rpy="0 0 0"/>
        <geometry>
          <mesh filename="package://srs004host/urdf/base1.stl" />
        </geometry>
        <material name="gray"/>
      </visual>
      <inertial>
        <mass value="0.130"/>
        <inertia ixx="0.0001" ixy="0" ixz="0" iyy="0.0001" iyz="0" izz="0.0001"/>
      </inertial>  
    </link>

    <joint name="${prefix}_base2_joint" type="continuous">
      <parent link="${prefix}_base1_link"/>
      <child link="${prefix}_base2_link"/>
      <origin rpy="0 0 0" xyz="0 0 0.016"/>
      <axis xyz="0 0 1"/>
      <dynamics damping="0.7"/>
    </joint>

    <link name="${prefix}_base2_link">
      <visual>
        <origin xyz="0 0 0" rpy="0 0 0"/>
        <geometry>
          <mesh filename="package://srs004host/urdf/base2.stl" />
        </geometry>
        <material name="gray"/>
      </visual>
      <inertial>
        <mass value="0.190"/>
        <inertia ixx="0.001" ixy="0" ixz="0" iyy="0.001" iyz="0" izz="0.0001"/>
      </inertial>  
    </link>

    <joint name="${prefix}_gun_joint" type="continuous">
      <parent link="${prefix}_base2_link"/>
      <child link="${prefix}_gun_link"/>
      <origin rpy="0 0 0" xyz="0 0 0.070"/>
      <axis xyz="0 1 0"/>
      <dynamics damping="0.1"/>
    </joint>

    <link name="${prefix}_gun_link">
      <visual>
        <origin xyz="0 0 0" rpy="0 0 0"/>
        <geometry>
          <mesh filename="package://srs004host/urdf/gun.stl" />
        </geometry>
        <material name="light_red"/>
      </visual>
      <inertial>
        <mass value="0.190"/>
        <inertia ixx="0.0001" ixy="0" ixz="0" iyy="0.001" iyz="0" izz="0.001"/>
      </inertial>  
    </link>

    <!-- ===============  Transmission =============== -->

    <transmission name="${prefix}_base2_trans">
      <type>transmission_interface/SimpleTransmission</type>
      <joint name="${prefix}_base2_joint">
        <hardwareInterface>hardware_interface/PositionJointInterface</hardwareInterface>
      </joint>
      <actuator name="${prefix}_base2_motor">
        <hardwareInterface>hardware_interface/PositionJointInterface</hardwareInterface>
        <mechanicalReduction>1</mechanicalReduction>
      </actuator>
    </transmission>

    <transmission name="${prefix}_gun_trans">
      <type>transmission_interface/SimpleTransmission</type>
      <joint name="${prefix}_gun_joint">
        <hardwareInterface>hardware_interface/PositionJointInterface</hardwareInterface>
      </joint>
      <actuator name="${prefix}_gun_motor">
        <hardwareInterface>hardware_interface/PositionJointInterface</hardwareInterface>
        <mechanicalReduction>1</mechanicalReduction>
      </actuator>
    </transmission>


    <!-- ===============  Gazebo =============== -->

    <gazebo reference="${prefix}_base1_link">
      <mu1 value="0.8" />
      <mu2 value="0.8" />
      <material>Gazebo/Gray</material>
    </gazebo>

    <gazebo reference="${prefix}_base2_link">
      <mu1 value="0.8" />
      <mu2 value="0.8" />
      <material>Gazebo/Gray</material>
    </gazebo>

  </xacro:macro>
</robot>
